Traceback (most recent call last):
  File "/home/runner/work/stock-analysis/stock-analysis/.venv/lib/python3.13/site-packages/jupyter_core/utils/__init__.py", line 154, in wrapped
    asyncio.get_running_loop()
    ~~~~~~~~~~~~~~~~~~~~~~~~^^
RuntimeError: no running event loop

During handling of the above exception, another exception occurred:

Traceback (most recent call last):
  File "/home/runner/work/stock-analysis/stock-analysis/.venv/lib/python3.13/site-packages/jupyter_cache/executors/utils.py", line 58, in single_nb_execution
    executenb(
    ~~~~~~~~~^
        nb,
        ^^^
    ...<4 lines>...
        **kwargs,
        ^^^^^^^^^
    )
    ^
  File "/home/runner/work/stock-analysis/stock-analysis/.venv/lib/python3.13/site-packages/nbclient/client.py", line 1319, in execute
    return NotebookClient(nb=nb, resources=resources, km=km, **kwargs).execute()
           ~~~~~~~~~~~~~~~~~~~~~~~~~~~~~~~~~~~~~~~~~~~~~~~~~~~~~~~~~~~~~~~~~~~^^
  File "/home/runner/work/stock-analysis/stock-analysis/.venv/lib/python3.13/site-packages/jupyter_core/utils/__init__.py", line 158, in wrapped
    return loop.run_until_complete(inner)
           ~~~~~~~~~~~~~~~~~~~~~~~^^^^^^^
  File "/opt/hostedtoolcache/Python/3.13.7/x64/lib/python3.13/asyncio/base_events.py", line 725, in run_until_complete
    return future.result()
           ~~~~~~~~~~~~~^^
  File "/home/runner/work/stock-analysis/stock-analysis/.venv/lib/python3.13/site-packages/nbclient/client.py", line 709, in async_execute
    await self.async_execute_cell(
        cell, index, execution_count=self.code_cells_executed + 1
    )
  File "/home/runner/work/stock-analysis/stock-analysis/.venv/lib/python3.13/site-packages/nbclient/client.py", line 1062, in async_execute_cell
    await self._check_raise_for_error(cell, cell_index, exec_reply)
  File "/home/runner/work/stock-analysis/stock-analysis/.venv/lib/python3.13/site-packages/nbclient/client.py", line 918, in _check_raise_for_error
    raise CellExecutionError.from_cell_and_msg(cell, exec_reply_content)
nbclient.exceptions.CellExecutionError: An error occurred while executing the following cell:
------------------
# plot the data to verify your needs
mpl.plot(df, type="candle", style="yahoo")
------------------


[31m---------------------------------------------------------------------------[39m
[31mValueError[39m                                Traceback (most recent call last)
[36mCell[39m[36m [39m[32mIn[6][39m[32m, line 2[39m
[32m      1[39m [38;5;66;03m# plot the data to verify your needs[39;00m
[32m----> [39m[32m2[39m [43mmpl[49m[43m.[49m[43mplot[49m[43m([49m[43mdf[49m[43m,[49m[43m [49m[38;5;28;43mtype[39;49m[43m=[49m[33;43m"[39;49m[33;43mcandle[39;49m[33;43m"[39;49m[43m,[49m[43m [49m[43mstyle[49m[43m=[49m[33;43m"[39;49m[33;43myahoo[39;49m[33;43m"[39;49m[43m)[49m

[36mFile [39m[32m~/work/stock-analysis/stock-analysis/.venv/lib/python3.13/site-packages/mplfinance/plotting.py:417[39m, in [36mplot[39m[34m(data, **kwargs)[39m
[32m    414[39m [38;5;66;03m# translate alias types:[39;00m
[32m    415[39m config[[33m'[39m[33mtype[39m[33m'[39m] = _get_valid_plot_types(config[[33m'[39m[33mtype[39m[33m'[39m])
[32m--> [39m[32m417[39m dates,opens,highs,lows,closes,volumes = [43m_check_and_prepare_data[49m[43m([49m[43mdata[49m[43m,[49m[43m [49m[43mconfig[49m[43m)[49m
[32m    419[39m config[[33m'[39m[33mxlim[39m[33m'[39m] = _check_and_convert_xlim_configuration(data, config)
[32m    421[39m [38;5;28;01mif[39;00m config[[33m'[39m[33mtype[39m[33m'[39m] [38;5;129;01min[39;00m VALID_PMOVE_TYPES [38;5;129;01mand[39;00m config[[33m'[39m[33maddplot[39m[33m'[39m] [38;5;129;01mis[39;00m [38;5;129;01mnot[39;00m [38;5;28;01mNone[39;00m:

[36mFile [39m[32m~/work/stock-analysis/stock-analysis/.venv/lib/python3.13/site-packages/mplfinance/_arg_validators.py:74[39m, in [36m_check_and_prepare_data[39m[34m(data, config)[39m
[32m     72[39m [38;5;28;01mfor[39;00m col [38;5;129;01min[39;00m cols:
[32m     73[39m     [38;5;28;01mif[39;00m [38;5;129;01mnot[39;00m [38;5;28mall[39m( [38;5;28misinstance[39m(v,([38;5;28mfloat[39m,[38;5;28mint[39m)) [38;5;28;01mfor[39;00m v [38;5;129;01min[39;00m data[col] ):
[32m---> [39m[32m74[39m         [38;5;28;01mraise[39;00m [38;5;167;01mValueError[39;00m([33m'[39m[33mData for column [39m[33m"[39m[33m'[39m+[38;5;28mstr[39m(col)+[33m'[39m[33m"[39m[33m must be ALL float or int.[39m[33m'[39m)
[32m     76[39m [38;5;28;01mif[39;00m config[[33m'[39m[33mtz_localize[39m[33m'[39m]:
[32m     77[39m     dates   = mdates.date2num(data.index.tz_localize([38;5;28;01mNone[39;00m).to_pydatetime())

[31mValueError[39m: Data for column "Open" must be ALL float or int.

